Workbook

Sheet SUMMARY
A1: Date | B1: Zenith | C1: FCMB | D1: Union | E1: TOTAL
A2: 46266 | B2: =SUMIFS('01-09-2026'!C:C,'01-09-2026'!B:B,"Zenith") -> 22182300 | C2: =SUMIFS('01-09-2026'!C:C,'01-09-2026'!B:B,"FCMB") -> 43078600 | D2: =SUMIFS('01-09-2026'!C:C,'01-09-2026'!B:B,"Union") -> 15447550 | E2: =SUM(B2:D2) -> 80708450
A3: 46267 | B3: =SUMIFS('02-09-2026'!C:C,'02-09-2026'!B:B,"Zenith") -> 7829850 | C3: =SUMIFS('02-09-2026'!C:C,'02-09-2026'!B:B,"FCMB") -> 50040375 | D3: =SUMIFS('02-09-2026'!C:C,'02-09-2026'!B:B,"Union") -> 23630170 | E3: =SUM(B3:D3) -> 81500395
A4: 46268 | B4: =SUMIFS('03-09-2026'!C:C,'03-09-2026'!B:B,"Zenith") -> 19216500 | C4: =SUMIFS('03-09-2026'!C:C,'03-09-2026'!B:B,"FCMB") -> 47119710 | D4: =SUMIFS('03-09-2026'!C:C,'03-09-2026'!B:B,"Union") -> 18584450 | E4: =SUM(B4:D4) -> 84920660
A5: 46269 | B5: =SUMIFS('04-09-2026'!C:C,'04-09-2026'!B:B,"Zenith") -> 17635050 | C5: =SUMIFS('04-09-2026'!C:C,'04-09-2026'!B:B,"FCMB") -> 51921400 | D5: =SUMIFS('04-09-2026'!C:C,'04-09-2026'!B:B,"Union") -> 21693600 | E5: =SUM(B5:D5) -> 91250050
A6: 46270 | B6: =SUMIFS('05-09-2026'!C:C,'05-09-2026'!B:B,"Zenith") -> 0 | C6: =SUMIFS('05-09-2026'!C:C,'05-09-2026'!B:B,"FCMB") -> 2000000 | D6: =SUMIFS('05-09-2026'!C:C,'05-09-2026'!B:B,"Union") -> 0 | E6: =SUM(B6:D6) -> 2000000
A7: 46271 | B7: =SUMIFS('06-09-2026'!C:C,'06-09-2026'!B:B,"Zenith") -> 0 | C7: =SUMIFS('06-09-2026'!C:C,'06-09-2026'!B:B,"FCMB") -> 2000000 | D7: =SUMIFS('06-09-2026'!C:C,'06-09-2026'!B:B,"Union") -> 0 | E7: =SUM(B7:D7) -> 2000000
A8: 46272 | B8: =SUMIFS('07-09-2026'!C:C,'07-09-2026'!B:B,"Zenith") -> 63376600 | C8: =SUMIFS('07-09-2026'!C:C,'07-09-2026'!B:B,"FCMB") -> 100717135 | D8: =SUMIFS('07-09-2026'!C:C,'07-09-2026'!B:B,"Union") -> 57233890 | E8: =SUM(B8:D8) -> 2.2132763e+08
A9: 46273 | B9: =SUMIFS('08-09-2026'!C:C,'08-09-2026'!B:B,"Zenith") -> 24628401 | C9: =SUMIFS('08-09-2026'!C:C,'08-09-2026'!B:B,"FCMB") -> 49156625 | D9: =SUMIFS('08-09-2026'!C:C,'08-09-2026'!B:B,"Union") -> 24077840 | E9: =SUM(B9:D9) -> 97862866
A10: 46274 | B10: =SUMIFS('09-09-2026'!C:C,'09-09-2026'!B:B,"Zenith") -> 30697850 | C10: =SUMIFS('09-09-2026'!C:C,'09-09-2026'!B:B,"FCMB") -> 44969835 | D10: =SUMIFS('09-09-2026'!C:C,'09-09-2026'!B:B,"Union") -> 29181970 | E10: =SUM(B10:D10) -> 104849655
A11: 46275 | B11: =SUMIFS('10-09-2026'!C:C,'10-09-2026'!B:B,"Zenith") -> 19136450 | C11: =SUMIFS('10-09-2026'!C:C,'10-09-2026'!B:B,"FCMB") -> 34190965 | D11: =SUMIFS('10-09-2026'!C:C,'10-09-2026'!B:B,"Union") -> 21512370 | E11: =SUM(B11:D11) -> 74839785
A12: 46276 | B12: =SUMIFS('11-09-2026'!C:C,'11-09-2026'!B:B,"Zenith") -> 31132200 | C12: =SUMIFS('11-09-2026'!C:C,'11-09-2026'!B:B,"FCMB") -> 47867125 | D12: =SUMIFS('11-09-2026'!C:C,'11-09-2026'!B:B,"Union") -> 25590830 | E12: =SUM(B12:D12) -> 104590155
A13: 46277 | B13: =SUMIFS('12-09-2026'!C:C,'12-09-2026'!B:B,"Zenith") -> 0 | C13: =SUMIFS('12-09-2026'!C:C,'12-09-2026'!B:B,"FCMB") -> 1000000 | D13: =SUMIFS('12-09-2026'!C:C,'12-09-2026'!B:B,"Union") -> 0 | E13: =SUM(B13:D13) -> 1000000
A14: 46278 | B14: =SUMIFS('13-09-2026'!C:C,'13-09-2026'!B:B,"Zenith") -> 0 | C14: =SUMIFS('13-09-2026'!C:C,'13-09-2026'!B:B,"FCMB") -> 0 | D14: =SUMIFS('13-09-2026'!C:C,'13-09-2026'!B:B,"Union") -> 0 | E14: =SUM(B14:D14) -> 0
A15: 46279 | B15: =SUMIFS('14-09-2026'!C:C,'14-09-2026'!B:B,"Zenith") -> 58972150 | C15: =SUMIFS('14-09-2026'!C:C,'14-09-2026'!B:B,"FCMB") -> 115257255 | D15: =SUMIFS('14-09-2026'!C:C,'14-09-2026'!B:B,"Union") -> 57078520 | E15: =SUM(B15:D15) -> 231307925
A16: 46280 | B16: =SUMIFS('15-09-2026'!C:C,'15-09-2026'!B:B,"Zenith") -> 18627500 | C16: =SUMIFS('15-09-2026'!C:C,'15-09-2026'!B:B,"FCMB") -> 38485475 | D16: =SUMIFS('15-09-2026'!C:C,'15-09-2026'!B:B,"Union") -> 26036340 | E16: =SUM(B16:D16) -> 83149315
A17: 46281 | B17: =SUMIFS('16-09-2026'!C:C,'16-09-2026'!B:B,"Zenith") -> 18893600 | C17: =SUMIFS('16-09-2026'!C:C,'16-09-2026'!B:B,"FCMB") -> 47779025 | D17: =SUMIFS('16-09-2026'!C:C,'16-09-2026'!B:B,"Union") -> 20271200 | E17: =SUM(B17:D17) -> 86943825
A18: 46282 | B18: =SUMIFS('17-09-2026'!C:C,'17-09-2026'!B:B,"Zenith") -> 23003450 | C18: =SUMIFS('17-09-2026'!C:C,'17-09-2026'!B:B,"FCMB") -> 31502740 | D18: =SUMIFS('17-09-2026'!C:C,'17-09-2026'!B:B,"Union") -> 24362800 | E18: =SUM(B18:D18) -> 78868990
A19: 46283 | B19: =SUMIFS('18-09-2026'!C:C,'18-09-2026'!B:B,"Zenith") -> 32682600 | C19: =SUMIFS('18-09-2026'!C:C,'18-09-2026'!B:B,"FCMB") -> 38668485 | D19: =SUMIFS('18-09-2026'!C:C,'18-09-2026'!B:B,"Union") -> 32744180 | E19: =SUM(B19:D19) -> 104095265
A20: 46284 | B20: =SUMIFS('19-09-2026'!C:C,'19-09-2026'!B:B,"Zenith") -> 0 | C20: =SUMIFS('19-09-2026'!C:C,'19-09-2026'!B:B,"FCMB") -> 0 | D20: =SUMIFS('19-09-2026'!C:C,'19-09-2026'!B:B,"Union") -> 0 | E20: =SUM(B20:D20) -> 0
A21: 46285 | B21: =SUMIFS('20-09-2026'!C:C,'20-09-2026'!B:B,"Zenith") -> 0 | C21: =SUMIFS('20-09-2026'!C:C,'20-09-2026'!B:B,"FCMB") -> 0 | D21: =SUMIFS('20-09-2026'!C:C,'20-09-2026'!B:B,"Union") -> 0 | E21: =SUM(B21:D21) -> 0
A22: 46286 | B22: =SUMIFS('21-09-2026'!C:C,'21-09-2026'!B:B,"Zenith") -> 90748750 | C22: =SUMIFS('21-09-2026'!C:C,'21-09-2026'!B:B,"FCMB") -> 125393290 | D22: =SUMIFS('21-09-2026'!C:C,'21-09-2026'!B:B,"Union") -> 64740190 | E22: =SUM(B22:D22) -> 280882230
A23: 46287 | B23: =SUMIFS('22-09-2026'!C:C,'22-09-2026'!B:B,"Zenith") -> 30538800 | C23: =SUMIFS('22-09-2026'!C:C,'22-09-2026'!B:B,"FCMB") -> 53885640 | D23: =SUMIFS('22-09-2026'!C:C,'22-09-2026'!B:B,"Union") -> 64546120 | E23: =SUM(B23:D23) -> 148970560
A24: 46288 | B24: =SUMIFS('23-09-2026'!C:C,'23-09-2026'!B:B,"Zenith") -> 26238000 | C24: =SUMIFS('23-09-2026'!C:C,'23-09-2026'!B:B,"FCMB") -> 64536820 | D24: =SUMIFS('23-09-2026'!C:C,'23-09-2026'!B:B,"Union") -> 37115980 | E24: =SUM(B24:D24) -> 127890800
A25: 46289 | B25: =SUMIFS('24-09-2026'!C:C,'24-09-2026'!B:B,"Zenith") -> 20008900 | C25: =SUMIFS('24-09-2026'!C:C,'24-09-2026'!B:B,"FCMB") -> 41422565 | D25: =SUMIFS('24-09-2026'!C:C,'24-09-2026'!B:B,"Union") -> 31207580 | E25: =SUM(B25:D25) -> 92639045
A26: 46290 | B26: =SUMIFS('25-09-2026'!C:C,'25-09-2026'!B:B,"Zenith") -> 21567000 | C26: =SUMIFS('25-09-2026'!C:C,'25-09-2026'!B:B,"FCMB") -> 45038170 | D26: =SUMIFS('25-09-2026'!C:C,'25-09-2026'!B:B,"Union") -> 29843450 | E26: =SUM(B26:D26) -> 96448620

Sheet 01-09-2026
A1: Stations | B1: Bank Account | C1: Amount | D1: Depositor's Name | E1: Trans. Ref | F1: Lodgement Time | G1: Confirmed Y/N | H1: Confirmed By
A2: Agbara 1 | B2: ZENITH | C2: 277700 | D2: ADEKUNLE IBIKUNLE | E2: 626281 | G2: NO
A3: Agodi OBX | B3: FCMB | C3: 1610050 | D3: ALABI OMOWUNMI | E3: 188533 | F3: 11.02AM | G3: YES | H3: ABIMBOLA
A4: Alegi SGX
A5: Apata SGR | B5: FCMB | C5: 1209750 | D5: BABATUNDE EBENEZER | E5: 23487138 | G5: YES | H5: ABIMBOLA
A6: Bodija OBX | B6: FCMB | C6: 182600 | D6: IYIOLA QUADRI | E6: 25461631 | G6: YES | H6: ABIMBOLA
A7: Cargo 1 OBX | B7: FCMB | C7: 1303000 | D7: KOLAWOLE EDUN | E7: 22698737 | G7: YES | H7: ABIMBOLA
A8: Cargo 2 OBX | B8: UNION | C8: 1220200 | D8: JINAUD IBRAHIM | F8: 2.25PM | G8: YES | H8: LAWRENCE
A9: Challenge OBX | B9: FCMB | C9: 716000 | D9: ASISAT | E9: 23487121 | G9: YES | H9: ABIMBOLA
A10: Guru OBX | B10: UNION | C10: 2613900 | D10: OJUMOOLA | G10: YES | H10: LAWRENCE
A11: Iba 1
A12: IBA 2 | B12: ZENITH | C12: 6226400 | D12: TAIWO BUKOLA | E12: 6288138 | G12: NO
A13: Ife 1 OBX | B13: FCMB | C13: 1801250 | D13: ADEDIRAN MEMUNAT | E13: 22634741 | G13: YES | H13: ABIMBOLA
A14: Ife 2 OBX | B14: FCMB | C14: 398500 | D14: AKORIN OLAITAN | E14: 22634102 | G14: YES | H14: ABIMBOLA
A15: Ife 3 OBX | B15: FCMB | C15: 1976100 | D15: TEMIDAYO DAVID | E15: 193063 | F15: 11.16AM | G15: YES | H15: ABIMBOLA
A16: Igbesa AGS
A17: Ijebu 1 SGR | B17: FCMB | C17: 1015800 | D17: BABATUNDE AJAWESORO | E17: 179659 | F17: 10.34AM | G17: YES | H17: ABIMBOLA
A18: Ijebu 2 SGR | B18: FCMB | C18: 682800 | D18: ADENIJI ADUNOLA | E18: 1105633 | F18: 12.38PM | G18: YES | H18: ABIMBOLA
A19: Interchange SGR
A20: Itamaga SGR | B20: UNION | C20: 991800 | D20: BARAKAT | E20: FJB2624483713823 | F20: 2.43PM | G20: YES | H20: LAWRENCE
A21: Iwo 1 OBX | B21: UNION | C21: 951630 | D21: FUNMILAYO TALABI | E21: FJB2624483682717 | F21: 8.55AM | G21: YES | H21: LAWRENCE
A22: Iwo 2 Monatan OBX | B22: FCMB | C22: 780720 | D22: SAHEED ADEBOWALE | E22: 1102702 | F22: 12.19PM | G22: YES | H22: ABIMBOLA
A23: Jah Michael TA | B23: FCMB | C23: 1764800 | D23: OLAYEMI ELEGBEDE | E23: 168853 | F23: 9.55AM | G23: YES | H23: ABIMBOLA
A24: Moniya OBX
A25: Mowe SGR | B25: ZENITH | C25: 8152700 | D25: OWOYELE BUKOLA | E25: 6770051 | G25: NO
A26: Ogbomoso 1 | B26: FCMB | C26: 690250 | D26: JIDE OYEWOLE | G26: YES | H26: ABIMBOLA
A27: Ogbomoso 2 | B27: FCMB | C27: 492920 | D27: OGUNSOLA ADEMOLA | E27: 175267 | F27: 10.22AM | G27: YES | H27: ABIMBOLA
A28: Ogere 1
A29: Ogere 2
A30: Ogijo | B30: FCMB | C30: 1615750 | D30: AFOLABI MUBARAK | G30: YES | H30: ABIMBOLA
A31: Ojoo
A32: Olomi 1 | B32: FCMB | C32: 792150 | D32: DONALD NWAKWO | E32: 23487134 | G32: YES | H32: ABIMBOLA
A33: Olomi 2
A34: Olorunsogo | B34: FCMB | C34: 1157000 | D34: ADEPEJU TITILAYO | E34: 23487122 | G34: YES | H34: ABIMBOLA
A35: Oyo Ilora | B35: UNION | C35: 1523900 | D35: ABIOLA | F35: 12.37PM | G35: YES | H35: LAWRENCE
A36: Sagam 1
A37: Sagam 2 | B37: FCMB | C37: 1623000 | D37: AJAYI ENIOLA | F37: 2.42PM | G37: YES | H37: ABIMBOLA
A38: Sagam 3
A39: Sagam 4 | B39: UNION | C39: 3165800 | D39: OLUWABUSOLAMI | E39: 2952383 | G39: YES | H39: LAWRENCE
A40: Shapade
...

Sheet 02-09-2026
A1: Stations | B1: Bank Account | C1: Amount | D1: Depositor's Name | E1: Trans. Ref | F1: Lodgement Time | G1: Confirmed Y/N | H1: Confirmed By
A2: Agbara 1 | B2: ZENITH | C2: 2147000 | D2: ADEKUNLE IBIKUNLE | E2: 626265 | G2: NO
A3: Agodi OBX | B3: FCMB | C3: 742000 | D3: ALABI OMOWUNMI | E3: 191200 | F3: 1.57PM | G3: YES | H3: ABIMBOLA
A4: Alegi SGX
A5: Apata SGR | B5: FCMB | C5: 1056100 | D5: BABATUNDE EBENEZER | E5: 23480459 | G5: YES | H5: ABIMBOLA
A6: Bodija OBX | B6: FCMB | C6: 855900 | D6: IYIOLA QUADRI | E6: 25461666 | G6: YES | H6: ABIMBOLA
A7: Cargo 1 OBX | B7: FCMB | C7: 966900 | D7: KOLAWOLE EDUN | E7: 22698744 | G7: YES | H7: ABIMBOLA
A8: Cargo 2 OBX | B8: UNION | C8: 541150 | D8: JINAUD IBRAHIM | F8: 11.39AM | G8: YES | H8: LAWRENCE
A9: Challenge OBX
A10: Guru OBX | B10: UNION | C10: 5214250 | D10: OJUMOOLA | E10: 3.13PM | G10: YES | H10: LAWRENCE
A11: Iba 1 | B11: FCMB | C11: 3557000 | D11: GBOLAGADE AYOMIKUN | G11: YES | H11: ABIMBOLA
A12: IBA 2
A13: Ife 1 OBX | B13: FCMB | C13: 986100 | D13: ADEDIRAN MEMUNAT | E13: 165230 | F13: 9.43AM | G13: YES | H13: ABIMBOLA
A14: Ife 2 OBX | B14: FCMB | C14: 327000 | D14: AKORIN OLAITAN | E14: 183114 | F14: 12.39PM | G14: YES | H14: ABIMBOLA
A15: Ife 3 OBX | B15: FCMB | C15: 1040530 | D15: TEMIDAYO DAVID | E15: 164279 | F15: 9.35AM | G15: YES | H15: ABIMBOLA
A16: Igbesa AGS
A17: Ijebu 1 SGR | B17: FCMB | C17: 1388200 | D17: BABATUNDE AJAWESORO | E17: 25321876 | G17: YES | H17: ABIMBOLA
A18: Ijebu 2 SGR | B18: FCMB | C18: 754900 | D18: ADENIJI ADUNOLA | G18: YES | H18: ABIMBOLA
A19: Interchange SGR
A20: Itamaga SGR | B20: UNION | C20: 1750500 | D20: BARAKAT | E20: FJB2624583788988 | F20: 4.14PM | G20: YES | H20: LAWRENCE
A21: Iwo 1 OBX | B21: UNION | C21: 1208900 | D21: FUNMILAYO TALABI | E21: FJB2624583732568 | F21: 8.59AM | G21: YES | H21: LAWRENCE
A22: Iwo 2 Monatan OBX | B22: FCMB | C22: 1392800 | D22: SAHEED ADEBOWALE | E22: 190621 | F22: 1.51PM | G22: YES | H22: ABIMBOLA
A23: Jah Michael TA | B23: FCMB | C23: 1606600 | D23: OLAYEMI ELEGBEDE | E23: 165969 | F23: 9.48AM | G23: YES | H23: ABIMBOLA
A24: Moniya OBX
A25: Mowe SGR
A26: Ogbomoso 1 | B26: FCMB | C26: 884500 | D26: JIDE OYEWOLE | G26: YES | H26: ABIMBOLA
A27: Ogbomoso 2 | B27: FCMB | C27: 940095 | D27: OGUNSOLA ADEMOLA | G27: YES | H27: ABIMBOLA
A28: Ogere 1
A29: Ogere 2
A30: Ogijo | B30: FCMB | C30: 2125700 | D30: AFOLABI MUBARAK | E30: 23131302 | G30: YES | H30: ABIMBOLA
A31: Ojoo
A32: Olomi 1
A33: Olomi 2 | B33: FCMB | C33: 1946250 | D33: ASAKULA TAIWO | E33: 23480462 | G33: YES | H33: ABIMBOLA
A34: Olorunsogo | B34: FCMB | C34: 1288000 | D34: ADEPEJU TITILAYO | E34: 23487146 | G34: YES | H34: ABIMBOLA
A35: Oyo Ilora
A36: Sagam 1 | B36: UNION | C36: 6704100 | D36: GBADEBO TEMITOPE | E36: 5908926 | G36: YES | H36: LAWRENCE
A37: Sagam 2 | B37: FCMB | C37: 2558250 | D37: AJAYI ENIOLA | E37: 198959 | F37: 2.08PM | G37: YES | H37: ABIMBOLA
A38: Sagam 3 | B38: FCMB | C38: 1354100 | D38: MUSA OWOLABI | G38: YES | H38: ABIMBOLA
A39: Sagam 4 | B39: UNION | C39: 1996100 | D39: OLUWABUSOLAMI | E39: 8989 | G39: YES | H39: LAWRENCE
A40: Shapade
...

Sheet 03-09-2026
A1: Stations | B1: Bank Account | C1: Amount | D1: Depositor's Name | E1: Trans. Ref | F1: Lodgement Time | G1: Confirmed Y/N | H1: Confirmed By
A2: Agbara 1 | B2: ZENITH | C2: 2348500 | D2: ADEKUNLE IBIKUNLE | E2: 21286391 | G2: NO
A3: Agodi OBX | B3: FCMB | C3: 969850 | D3: ALABI OMOWUNMI | E3: 163118 | F3: 1.47PM | G3: YES | H3: ABIMBOLA
A4: Alegi SGX
A5: Apata SGR | B5: FCMB | C5: 1055950 | D5: BABATUNDE EBENEZER | E5: 23487258 | G5: YES | H5: ABIMBOLA
A6: Bodija OBX | B6: FCMB | C6: 818980 | D6: IYIOLA QUADRI | E6: 25461461 | G6: YES | H6: ABIMBOLA
A7: Cargo 1 OBX | B7: FCMB | C7: 817300 | D7: KOLAWOLE EDUN | E7: 22698764 | G7: YES | H7: ABIMBOLA
A8: Cargo 2 OBX | B8: UNION | C8: 767400 | D8: JINAUD IBRAHIM | G8: YES | H8: LAWRENCE
A9: Challenge OBX | B9: FCMB | C9: 1244450 | D9: ASISAT | E9: 23487255 | G9: YES | H9: ABIMBOLA
A10: Guru OBX | B10: UNION | C10: 4016750 | D10: OJUMOOLA | E10: FJB2624683786260 | F10: 2.58PM | G10: YES | H10: LAWRENCE
A11: Iba 1
A12: IBA 2 | B12: ZENITH | C12: 4203650 | D12: TAIWO BUKOLA | E12: 6288146 | G12: NO
A13: Ife 1 OBX | B13: FCMB | C13: 2504500 | D13: ADEDIRAN MEMUNAT | E13: 141331 | F13: 10.50AM | G13: YES | H13: ABIMBOLA
A14: Ife 2 OBX | B14: FCMB | C14: 461700 | D14: AKORIN OLAITAN | E14: 151518 | F14: 12.31PM | G14: YES | H14: ABIMBOLA
A15: Ife 3 OBX | B15: FCMB | C15: 1620820 | D15: TEMIDAYO DAVID | F15: 10.54AM | G15: YES | H15: ABIMBOLA
A16: Igbesa AGS
A17: Ijebu 1 SGR | B17: FCMB | C17: 1333450 | D17: BABATUNDE AJAWESORO | E17: 25321940 | G17: YES | H17: ABIMBOLA
A18: Ijebu 2 SGR
A19: Interchange SGR
A20: Itamaga SGR | B20: UNION | C20: 2011200 | D20: BARAKAT | E20: FJB2624583785861 | F20: 2.48PM | G20: YES | H20: LAWRENCE
A21: Iwo 1 OBX | B21: UNION | C21: 1252700 | D21: FUNMILAYO TALABI | E21: FJB2624683773372 | F21: 8.38AM | G21: YES | H21: LAWRENCE
A22: Iwo 2 Monatan OBX | B22: FCMB | C22: 1145900 | D22: SAHEED ADEBOWALE | E22: 163171 | F22: 1.52PM | G22: YES | H22: ABIMBOLA
A23: Jah Michael TA | B23: FCMB | C23: 2716650 | D23: OLAYEMI ELEGBEDE | F23: 5.53AM | G23: YES | H23: ABIMBOLA
A24: Moniya OBX
A25: Mowe SGR | B25: ZENITH | C25: 4863200 | D25: OGUNBIYI JOEL | E25: 6770055 | G25: NO
A26: Ogbomoso 1 | B26: FCMB | C26: 992200 | D26: JIDE OYEWOLE | G26: YES | H26: ABIMBOLA
A27: Ogbomoso 2 | B27: FCMB | C27: 685580 | D27: OGUNSOLA ADEMOLA | G27: YES | H27: ABIMBOLA
A28: Ogere 1
A29: Ogere 2
A30: Ogijo | B30: FCMB | C30: 2351900 | D30: AFOLABI MUBARAK | E30: 23131310 | G30: YES | H30: ABIMBOLA
A31: Ojoo
A32: Olomi 1 | B32: FCMB | C32: 773700 | D32: DONALD NWANKWO | E32: 23487254 | G32: YES | H32: ABIMBOLA
A33: Olomi 2
A34: Olorunsogo | B34: FCMB | C34: 905000 | D34: ADEPEJU TITILAYO | E34: 23487252 | G34: YES | H34: ABIMBOLA
A35: Oyo Ilora
A36: Sagam 1 | B36: UNION | C36: 4184300 | D36: GBADEBO TEMITOPE | E36: 4998982 | G36: YES | H36: LAWRENCE
A37: Sagam 2 | B37: FCMB | C37: 1415300 | D37: AJAYI ENIOLA | G37: YES | H37: ABIMBOLA
A38: Sagam 3
A39: Sagam 4 | B39: UNION | C39: 1572300 | D39: OLUWABUSOLAMI | E39: 952391 | G39: YES | H39: LAWRENCE
A40: Shapade
...

Sheet 04-09-2026
A1: Stations | B1: Bank Account | C1: Amount | D1: Depositor's Name | E1: Trans. Ref | F1: Lodgement Time | G1: Confirmed Y/N | H1: Confirmed By
A2: Agbara 1 | B2: ZENITH | C2: 1629000 | D2: ADEKUNLE IBIKUNLE | E2: 21286380 | G2: NO | I2: C
A3: Agodi OBX | B3: FCMB | C3: 1089060 | D3: ALABI OMOWUNMI | E3: 1239563 | F3: 1.11PM | G3: YES | H3: ABIMBOLA | I3: C
A4: Alegi SGX
A5: Apata SGR
A6: Bodija OBX | B6: FCMB | C6: 359600 | D6: IYIOLA QUADRI | E6: 2461474 | G6: YES | H6: ABIMBOLA | I6: C
A7: Cargo 1 OBX | B7: FCMB | C7: 1341900 | D7: KOLAWOLE EDUN | E7: 22698778 | G7: YES | H7: ABIMBOLA | I7: C
A8: Cargo 2 OBX | B8: UNION | C8: 1146750 | D8: JINAUD IBRAHIM | E8: 460246 | G8: YES | H8: ABIMBOLA | I8: E
A9: Challenge OBX | B9: FCMB | C9: 1060460 | D9: ASISAT | E9: 23487271 | G9: YES | H9: ABIMBOLA | I9: C
A10: Guru OBX | B10: UNION | C10: 3664150 | D10: OJUMOOLA | F10: 2.57PM | G10: YES | H10: LAWRENCE | I10: C
A11: Iba 1 | B11: FCMB | C11: 3241650 | D11: GBOLAGADE AYOMIKUN | E11: 1229323 | F11: 11.44AM | G11: YES | H11: ABIMBOLA | I11: C
A12: IBA 2 | B12: ZENITH | C12: 3028600 | D12: TAIWO BUKOLA | E12: 628831 | G12: NO | I12: C
A13: Ife 1 OBX | B13: FCMB | C13: 854400 | D13: ADEDIRAN MEMUNAT | E13: 1224107 | F13: 10.42AM | G13: YES | H13: ABIMBOLA | I13: C
A14: Ife 2 OBX | B14: FCMB | C14: 303265 | D14: AKORIN OLAITAN | G14: YES | H14: ABIMBOLA | I14: C
A15: Ife 3 OBX | B15: FCMB | C15: 1121770 | D15: TEMIDAYO DAVID | E15: 1222329 | F15: 10.28AM | G15: YES | H15: ABIMBOLA | I15: C
A16: Igbesa AGS
A17: Ijebu 1 SGR | B17: FCMB | C17: 2255200 | D17: BABATUNDE AJAWESORO | E17: 25321993 | G17: YES | H17: ABIMBOLA | I17: C
A18: Ijebu 2 SGR | B18: FCMB | C18: 1693050 | D18: ADENIJI ADUNOLA | E18: 1232106 | G18: YES | H18: ABIMBOLA | I18: C
A19: Interchange SGR
A20: Itamaga SGR | B20: UNION | C20: 2907100 | D20: BARAKAT | E20: FJB2624783830420 | F20: 3.47PM | G20: YES | H20: ABIMBOLA | I20: E
A21: Iwo 1 OBX | B21: UNION | C21: 1259400 | D21: FUNMILAYO TALABI | E21: FJB2624783800490 | F21: 8.55AM | G21: YES | H21: LAWRENCE | I21: C
A22: Iwo 2 Monatan OBX | B22: FCMB | C22: 1459850 | D22: SAHEED ADEBOWALE | E22: 1239598 | F22: 12.51PM | G22: YES | H22: ABIMBOLA | I22: C
A23: Jah Michael TA | B23: FCMB | C23: 2643750 | D23: OLAYEMI ELEGBEDE | E23: 1222080 | F23: 10.22AM | G23: YES | H23: ABIMBOLA | I23: C
A24: Moniya OBX | B24: FCMB | C24: 1514650 | D24: ESTHER | E24: 25461401 | G24: YES | H24: ABIMBOLA | I24: C
A25: Mowe SGR | B25: ZENITH | C25: 3963700 | D25: OGUNBIYI JOEL | E25: 48978 | G25: NO | I25: E
A26: Ogbomoso 1 | B26: FCMB | C26: 974200 | D26: JIDE OYEWOLE | G26: YES | H26: ABIMBOLA | I26: C
A27: Ogbomoso 2 | B27: FCMB | C27: 888575 | D27: OGUNSOLA ADEMOLA | G27: YES | H27: ABIMBOLA | I27: C
A28: Ogere 1
A29: Ogere 2
A30: Ogijo
A31: Ojoo
A32: Olomi 1 | B32: FCMB | C32: 632350 | D32: DONALD NWANKWO | E32: 23487272 | G32: YES | H32: ABIMBOLA | I32: C
A33: Olomi 2 | B33: FCMB | C33: 1620700 | D33: ASAKULA TAIWO | E33: 23487273 | G33: YES | H33: ABIMBOLA | I33: C
A34: Olorunsogo | B34: FCMB | C34: 1811000 | D34: ADEPEJU TITILAYO | E34: 23487268 | G34: YES | H34: ABIMBOLA | I34: C
A35: Oyo Ilora | B35: UNION | C35: 1468300 | D35: ABIOLA | F35: 10.47AM | G35: YES | H35: LAWRENCE | I35: C
A36: Sagam 1 | B36: UNION | C36: 5377000 | D36: GBADEBO TEMITOPE | E36: 962005 | G36: YES | H36: LAWRENCE
A37: Sagam 2 | B37: FCMB | C37: 3581200 | D37: AJAYI ENIOLA | E37: 22769175 | G37: YES | H37: ABIMBOLA | I37: C
A38: Sagam 3
A39: Sagam 4
A40: Shapade
...

Sheet 05-09-2026
A1: Stations | B1: Bank Account | C1: Amount | D1: Depositor's Name | E1: Trans. Ref | F1: Lodgement Time | G1: Confirmed Y/N | H1: Confirmed By
A2: Agbara 1
A3: Agodi OBX
A4: Alegi SGX
A5: Apata SGR
A6: Bodija OBX
A7: Cargo 1 OBX
A8: Cargo 2 OBX
A9: Challenge OBX
A10: Guru OBX
A11: Iba 1
A12: IBA 2
A13: Ife 1 OBX
... A22: Iwo 2 Monatan OBX
A23: Jah Michael TA | B23: FCMB | C23: 2000000 | D23: FADENI & SONS | F23: 7.25AM
A24: Moniya OBX
A25: Mowe SGR
A26: Ogbomoso 1
A27: Ogbomoso 2
A28: Ogere 1
A29: Ogere 2
A30: Ogijo
A31: Ojoo
A32: Olomi 1
A33: Olomi 2
A34: Olorunsogo
A35: Oyo Ilora
... A60: Ojogbe
A61: TOTAL | C61: =SUM(C2:C60) -> 2000000

Sheet 06-09-2026
A1: Stations | B1: Bank Account | C1: Amount | D1: Depositor's Name | E1: Trans. Ref | F1: Lodgement Time | G1: Confirmed Y/N | H1: Confirmed By
A2: Agbara 1
A3: Agodi OBX
A4: Alegi SGX
A5: Apata SGR
A6: Bodija OBX
A7: Cargo 1 OBX
A8: Cargo 2 OBX
A9: Challenge OBX
A10: Guru OBX
A11: Iba 1
A12: IBA 2
A13: Ife 1 OBX
... A22: Iwo 2 Monatan OBX
A23: Jah Michael TA | B23: FCMB | C23: 2000000 | D23: FADENI & SONS | F23: 6.38AM | G23: YES | H23: ABIMBOLA
A24: Moniya OBX
A25: Mowe SGR
A26: Ogbomoso 1
A27: Ogbomoso 2
A28: Ogere 1
A29: Ogere 2
A30: Ogijo
A31: Ojoo
A32: Olomi 1
A33: Olomi 2
A34: Olorunsogo
A35: Oyo Ilora
... A60: Ojogbe
A61: TOTAL | C61: =SUM(C2:C60) -> 2000000

Sheet 07-09-2026
A1: Stations | B1: Bank Account | C1: Amount | D1: Depositor's Name | E1: Trans. Ref | F1: Lodgement Time | G1: Confirmed Y/N | H1: Confirmed By
A2: Agbara 1 | B2: ZENITH | C2: 7467900 | D2: ADEKUNLE IBIKUNLE | E2: 21286375 | G2: NO
A3: Agodi OBX | B3: FCMB | C3: 2935750 | D3: ALABI OMOWUNMI | E3: 1253726 | F3: 3.12PM | G3: YES | H3: ABIMBOLA
A4: Alegi SGX
A5: Apata SGR | B5: FCMB | C5: 2619600 | E5: 23487295 | G5: YES | H5: ABIMBOLA
A6: Bodija OBX | B6: FCMB | C6: 2032590 | D6: IYIOLA QUADRI | E6: 25461357 | G6: YES | H6: ABIMBOLA
A7: Cargo 1 OBX | B7: FCMB | C7: 3774500 | D7: KOLAWOLE EDUN | E7: 22698783 | G7: YES | H7: ABIMBOLA
A8: Cargo 2 OBX | B8: UNION | C8: 2708600 | D8: JINAUD IBRAHIM | F8: 12.21PM | G8: YES | H8: LAWRENCE
A9: Challenge OBX | B9: FCMB | C9: 2436850 | D9: ASISAT | E9: 23487283 | G9: YES | H9: ABIMBOLA
A10: Guru OBX | B10: UNION | C10: 17136600 | D10: OJUMOOLA | E10: FJB2625083881137 | F10: 4.21PM | G10: YES | H10: LAWRENCE
A11: Iba 1 | B11: FCMB | C11: 5038800 | D11: GBOLAGADE AYOMIKUN | E11: 1233981 | F11: 12.20PM | G11: YES | H11: ABIMBOLA
A12: IBA 2 | B12: ZENITH | C12: 3823250 | D12: TAIWO BUKOLA | E12: 42641 | G12: NO
A13: Ife 1 OBX | B13: FCMB | C13: 3024170 | D13: ADEDIRAN MEMUNAT | G13: YES | H13: ABIMBOLA
A14: Ife 2 OBX | B14: FCMB | C14: 845450 | D14: AKORIN OLAITAN | E14: 1221249 | F14: 10.12AM | G14: YES | H14: ABIMBOLA
A15: Ife 3 OBX | B15: FCMB | C15: 4472440 | D15: TEMIDAYO DAVID | G15: YES | H15: ABIMBOLA
A16: Igbesa AGS
A17: Ijebu 1 SGR | B17: FCMB | C17: 4361200 | D17: BABATUNDE AJAWESORO | E17: 24596051 | G17: YES | H17: ABIMBOLA
A18: Ijebu 2 SGR | B18: FCMB | C18: 2270900 | D18: ADENIJI ADUNOLA | G18: YES | H18: ABIMBOLA
A19: Interchange SGR
A20: Itamaga SGR | B20: UNION | C20: 8722100 | D20: BARAKAT | E20: FJB2625083865341 | F20: 1.13PM | G20: YES | H20: LAWRENCE
A21: Iwo 1 OBX | B21: UNION | C21: 3133350 | D21: FUNMILAYO TALABI | E21: FJB262583852908 | F21: 9.04AM | G21: YES | H21: LAWRENCE
A22: Iwo 2 Monatan OBX | B22: FCMB | C22: 4606050 | D22: SAHEED ADEBOWALE | E22: 1246980 | F22: 2.14PM | G22: YES | H22: ABIMBOLA
A23: Jah Michael TA | B23: FCMB | C23: 1000000 | D23: FADENI & SONS | F23: 7.07AM | G23: YES | H23: ABIMBOLA
A24: Jah Michael TA | B24: FCMB | C24: 2286900 | D24: POPOOLA ADISA | E24: 1222078 | F24: 10.10AM | G24: YES | H24: ABIMBOLA
A25: Moniya OBX
A26: Mowe SGR | B26: ZENITH | C26: 11378400 | D26: OGUNBIYI JOEL | E26: 6472831 | G26: NO
A27: Ogbomoso 1 | B27: FCMB | C27: 3214110 | D27: JIDE OYEWOLE | G27: YES | H27: ABIMBOLA
A28: Ogbomoso 2 | B28: FCMB | C28: 1899105 | D28: OGUNSOLA ADEMOLA | G28: YES | H28: ABIMBOLA
A29: Ogere 1
A30: Ogere 2
A31: Ogijo
A32: Ojoo
A33: Olomi 1 | B33: FCMB | C33: 1134520 | D33: DONALD NWANKWO | E33: 23487289 | G33: YES | H33: ABIMBOLA
A34: Olomi 2 | B34: FCMB | C34: 2003250 | D34: ASAKULA TAIWO | E34: 23487287 | G34: YES | H34: ABIMBOLA
A35: Olorunsogo | B35: FCMB | C35: 3594700 | D35: ADEPEJU TITILAYO | E35: 23487285 | G35: YES | H35: LAWRENCE
A36: Oyo Ilora | B36: UNION | C36: 2433300 | D36: ABIOLA | F36: 11.32AM | G36: YES | H36: LAWRENCE
A37: Sagam 1 | B37: UNION | C37: 7424970 | D37: GBADEBO TEMITOPE | E37: 952011 | G37: YES | H37: LAWRENCE
A38: Sagam 2 | B38: FCMB | C38: 4708500 | D38: AJAYI ENIOLA | E38: 1242473 | F38: 1.30PM | G38: YES | H38: ABIMBOLA
A39: Sagam 3 | B39: FCMB | C39: 1401450 | D39: OWOLABI | G39: YES | H39: ABIMBOLA
A40: Sagam 4 | B40: UNION | C40: 630400 | D40: OLUWABUSOLAMI | E40: 9439 | G40: YES | H40: LAWRENCE
...

Sheet 08-09-2026
A1: Stations | B1: Bank Account | C1: Amount | D1: Depositor's Name | E1: Trans. Ref | F1: Lodgement Time | G1: Confirmed Y/N | H1: Confirmed By
A2: Agbara 1 | B2: ZENITH | C2: 2699901 | D2: ADEKUNLE IBIKUNLE | E2: 360923 | G2: NO
A3: Agodi OBX | B3: FCMB | C3: 1611650 | D3: ALABI OMOWUNMI | E3: 165110 | F3: 4.04PM | G3: YES | H3: ABIMBOLA
A4: Alegi SGX
A5: Apata SGR | B5: FCMB | C5: 1380350 | D5: BABATUNDE EBENEZER | E5: 23480815 | G5: YES | H5: ABIMBOLA
A6: Bodija OBX | B6: FCMB | C6: 842120 | D6: IYIOLA QUADRI | E6: 25461797 | G6: YES | H6: ABIMBOLA
A7: Cargo 1 OBX | B7: FCMB | C7: 1393800 | D7: KOLAWOLE EDUN | E7: 22698797 | G7: YES | H7: ABIMBOLA
A8: Cargo 2 OBX | B8: UNION | C8: 1286120 | D8: JINAUD IBRAHIM | F8: 12.01PM | G8: YES | H8: LAWRENCE
A9: Challenge OBX | B9: FCMB | C9: 859000 | D9: ASISAT | E9: 23480802 | G9: YES | H9: ABIMBOLA
A10: Guru OBX | B10: UNION | C10: 5719400 | D10: OJUMOOLA | F10: 2.32PM | G10: YES | H10: LAWRENCE
A11: Iba 1
A12: IBA 2
A13: Ife 1 OBX | B13: FCMB | C13: 2165800 | D13: ADEDIRAN MEMUNAT | E13: 132362 | F13: 10.17AM | G13: YES | H13: ABIMBOLA
A14: Ife 2 OBX | B14: FCMB | C14: 474000 | D14: AKORIN OLAITAN | E14: 143806 | F14: 12.22PM | G14: YES | H14: ABIMBOLA
A15: Ife 3 OBX | B15: FCMB | C15: 1766020 | D15: TEMIDAYO DAVID | E15: 132340 | F15: 10.14AM | G15: YES | H15: ABIMBOLA
A16: Igbesa AGS
A17: Ijebu 1 SGR | B17: FCMB | C17: 900150 | D17: BABATUNDE AJAWESORO | E17: 24596110 | G17: YES | H17: ABIMBOLA
A18: Ijebu 2 SGR | B18: FCMB | C18: 1477100 | D18: ADENIJI ADUNOLA | G18: YES | H18: ABIMBOLA
A19: Interchange SGR
A20: Itamaga SGR | B20: UNION | C20: 3230800 | D20: BARAKAT | E20: FJB2625183904990 | F20: 1.25PM | G20: YES | H20: LAWRENCE
A21: Iwo 1 OBX | B21: UNION | C21: 1427950 | D21: FUNMILAYO TALABI | E21: FJB2625183888901 | F21: 8.38AM | G21: YES | H21: LAWRENCE
A22: Iwo 2 Monatan OBX | B22: FCMB | C22: 1873700 | D22: SAHEED ADEBOWALE | E22: 160295 | F22: 3.02PM | G22: YES | H22: ABIMBOLA
A23: Jah Michael TA | B23: FCMB | C23: 2400000 | D23: FADENI & SONS | F23: 7.34AM | G23: YES | H23: ABIMBOLA
A24: Moniya OBX
A25: Mowe SGR
A26: Ogbomoso 1 | B26: FCMB | C26: 1011500 | D26: JIDE OYEWOLE | E26: 133425 | F26: 10.18AM | G26: YES | H26: ABIMBOLA
A27: Ogbomoso 2 | B27: FCMB | C27: 695815 | D27: OGUNSOLA ADEMOLA | G27: YES | H27: ABIMBOLA
A28: Ogere 1
A29: Ogere 2
A30: Ogijo | B30: FCMB | C30: 3878050 | D30: MUBARAK AFOLABI | E30: 23131322 | G30: YES | H30: ABIMBOLA
A31: Ojoo
A32: Olomi 1 | B32: FCMB | C32: 686660 | D32: DONALD NWANKWO | E32: 23480803 | G32: YES | H32: ABIMBOLA
A33: Olomi 2
A34: Olorunsogo | B34: FCMB | C34: 1652750 | D34: ADEPEJU TITILAYO | E34: 23487299 | G34: YES | H34: ABIMBOLA
A35: Oyo Ilora
A36: Sagam 1 | B36: UNION | C36: 3772800 | D36: GBADEBO TEMITOPE | E36: 197957 | G36: YES | H36: LAWRENCE
A37: Sagam 2 | B37: FCMB | C37: 523200 | D37: AJAYI ENIOLA | E37: 143423 | F37: 12.18PM | G37: YES | H37: ABIMBOLA
A38: Sagam 3
A39: Sagam 4 | B39: UNION | C39: 1104450 | D39: OLUWABUSOLAMI | E39: 1999408 | G39: YES | H39: LAWRENCE
A40: Shapade
...

Sheet 09-09-2026
A1: Stations | B1: Bank Account | C1: Amount | D1: Depositor's Name | E1: Trans. Ref | F1: Lodgement Time | G1: Confirmed Y/N | H1: Confirmed By
A2: Agbara 1 | B2: ZENITH | C2: 2684900 | D2: ADEKUNLE IBIKUNLE | E2: 360929 | G2: NO | I2: C
A3: Agodi OBX | B3: FCMB | C3: 536150 | D3: ALABI OMOWUNMI | G3: YES | H3: ABIMBOLA | I3: C
A4: Alegi SGX
A5: Apata SGR | B5: FCMB | C5: 1382050 | D5: BABATUNDE EBENEZER | E5: 23480828 | G5: YES | H5: ABIMBOLA | I5: C
A6: Bodija OBX | B6: FCMB | C6: 930000 | D6: IYIOLA QUADRI | E6: 25461380 | G6: YES | H6: ABIMBOLA | I6: C
A7: Cargo 1 OBX | B7: FCMB | C7: 360800 | D7: KOLAWOLE EDUN | E7: 23480826 | G7: YES | H7: ABIMBOLA | I7: C
A8: Cargo 2 OBX | B8: UNION | C8: 1338800 | D8: JINAUD IBRAHIM | E8: 339769 | G8: YES | H8: LAWRENCE | I8: C
A9: Challenge OBX | B9: FCMB | C9: 834400 | D9: ASISAT | E9: 23480816 | G9: YES | H9: ABIMBOLA | I9: C
A10: Guru OBX | B10: UNION | C10: 3298100 | D10: OJUMOOLA | F10: 1.53PM | I10: C
A11: Iba 1 | B11: UNION | C11: 4288550 | D11: ABOLAGADE AYOMIKUN | G11: YES | H11: ABIMBOLA | I11: C
A12: IBA 2 | B12: ZENITH | C12: 5965950 | D12: TAIWO BUKOLA | E12: 4577481 | I12: C
A13: Ife 1 OBX | B13: FCMB | C13: 2048300 | D13: ADEDIRAN MEMUNAT | G13: YES | H13: ABIMBOLA | I13: C
A14: Ife 2 OBX | B14: FCMB | C14: 382800 | D14: AKORIN OLAITAN | E14: 149087 | G14: YES | H14: ABIMBOLA
A15: Ife 3 OBX | B15: FCMB | C15: 1314400 | D15: TEMIDAYO DAVID | E15: 115520 | F15: 9.13AM | G15: YES | H15: ABIMBOLA | I15: C
A16: Igbesa AGS
A17: Ijebu 1 SGR | B17: FCMB | C17: 1550000 | D17: BABATUNDE AJAWESORO | E17: 118991 | F17: 9.51AM | G17: YES | H17: ABIMBOLA | I17: C
A18: Ijebu 2 SGR
A19: Interchange SGR
A20: Itamaga SGR | B20: UNION | C20: 2742900 | D20: BARAKAT | E20: FJB2625283851883 | F20: 3.21PM | G20: YES | H20: LAWRENCE | I20: C
A21: Iwo 1 OBX | B21: UNION | C21: 1015550 | D21: FUNMILAYO TALABI | E21: FJB2625283928873 | F21: 8.58AM | G21: YES | H21: LAWRENCE | I21: C
A22: Iwo 2 Monatan OBX | B22: FCMB | C22: 1436770 | D22: SAHEED ADEBOWALE | G22: YES | H22: ABIMBOLA | I22: C
A23: Jah Michael TA | B23: FCMB | C23: 2983150 | D23: FADENI & SONS | E23: 121988 | G23: YES | H23: ABIMBOLA | I23: C
A24: Moniya OBX | B24: FCMB | C24: 821800 | D24: ESTHER | E24: 25461383 | G24: YES | H24: ABIMBOLA | I24: C
A25: Mowe SGR | B25: ZENITH | C25: 5613200 | D25: OWOYELE BUKOLA | E25: 6770072 | G25: NO
A26: Ogbomoso 1 | B26: FCMB | C26: 808850 | D26: JIDE OYEWOLE | E26: 119135 | F26: 10.05AM | G26: YES | H26: ABIMBOLA | I26: C
A27: Ogbomoso 2 | B27: FCMB | C27: 534105 | D27: OGUNSOLA ADEMOLA | G27: YES | H27: ABIMBOLA | I27: C
A28: Ogere 1
A29: Ogere 2
A30: Ogijo | B30: FCMB | C30: 2411700 | D30: MUBARAK AFOLABI | E30: 23131325 | G30: YES | H30: ABIMBOLA | I30: C
A31: Ojoo
A32: Olomi 1
A33: Olomi 2 | B33: FCMB | C33: 2002800 | D33: ASAKULA TAIWO | E33: 23480819 | G33: YES | H33: ABIMBOLA | I33: C
A34: Olorunsogo | B34: FCMB | C34: 1967850 | D34: ADEPEJU TITILAYO | E34: 23480817 | G34: YES | H34: ABIMBOLA | I34: C
A35: Oyo Ilora | B35: UNION | C35: 2961000 | D35: ABIOLA | F35: 12.17AM | G35: YES | H35: LAWRENCE | I35: C
A36: Sagam 1 | B36: UNION | C36: 4118800 | D36: GBADEBO TEMITOPE | E36: 9427 | G36: YES | H36: LAWRENCE | I36: C
A37: Sagam 2 | B37: FCMB | C37: 1811000 | D37: AJAYI ENIOLA | E37: 129463 | F37: 11.58AM | G37: YES | H37: ABIMBOLA | I37: C
A38: Sagam 3
A39: Sagam 4 | B39: UNION | C39: 711100 | D39: OLUWABUSOLAMI | E39: 1952021 | G39: YES | H39: LAWRENCE | I39: C
A40: Shapade
...

Sheet 10-09-2026
A1: Stations | B1: Bank Account | C1: Amount | D1: Depositor's Name | E1: Trans. Ref | F1: Lodgement Time | G1: Confirmed Y/N | H1: Confirmed By
A2: Agbara 1 | B2: ZENITH | C2: 2140200 | D2: ADEKUNLE IBIKUNLE | E2: 360932 | G2: NO
A3: Agodi OBX | B3: FCMB | C3: 1236050 | D3: ALABI OMOWUNMI | G3: YES | H3: ABIMBOLA
A4: Alegi SGX
A5: Apata SGR | B5: FCMB | C5: 1164620 | D5: BABATUNDE EBENEZER | E5: 23480844 | G5: YES | H5: ABIMBOLA
A6: Bodija OBX | B6: FCMB | C6: 795600 | D6: IYIOLA QUADRI | E6: 25461442 | G6: YES | H6: ABIMBOLA
A7: Cargo 1 OBX | B7: FCMB | C7: 1289200 | D7: KOLAWOLE EDUN | E7: 23480715 | G7: YES | H7: ABIMBOLA
A8: Cargo 2 OBX | B8: UNION | C8: 618650 | D8: JINAUD IBRAHIM | E8: FJB2625383984 | F8: 2.52PM | G8: YES | H8: LAWRENCE
A9: Challenge OBX | B9: FCMB | C9: 1246750 | D9: ASISAT | E9: 23480833 | G9: YES | H9: ABIMBOLA
A10: Guru OBX | B10: UNION | C10: 3793150 | D10: OJUMOOLA | G10: YES | H10: LAWRENCE
A11: Iba 1
A12: IBA 2 | B12: ZENITH | C12: 3196150 | D12: TAIWO BUKOLA | E12: 4577486 | G12: NO
A13: Ife 1 OBX | B13: FCMB | C13: 1222000 | D13: ADEDIRAN MEMUNAT | G13: YES | H13: ABIMBOLA
A14: Ife 2 OBX | B14: FCMB | C14: 340300 | D14: AKORIN OLAITAN | E14: 130431 | F14: 12.46PM | G14: YES | H14: ABIMBOLA
A15: Ife 3 OBX | B15: FCMB | C15: 1302130 | D15: TEMIDAYO DAVID | G15: YES | H15: ABIMBOLA
A16: Igbesa AGS
A17: Ijebu 1 SGR | B17: FCMB | C17: 1569000 | D17: BABATUNDE AJAWESORO | G17: YES | H17: ABIMBOLA
A18: Ijebu 2 SGR | B18: FCMB | C18: 883400 | D18: ADENIJI ADUNOLA | G18: YES | H18: ABIMBOLA
A19: Interchange SGR
A20: Itamaga SGR | B20: UNION | C20: 2506500 | D20: BARAKAT | E20: FJB2625383887615 | F20: 4.25PM | G20: YES | H20: LAWRENCE
A21: Iwo 1 OBX | B21: UNION | C21: 1376400 | D21: FUNMILAYO TALABI | E21: FJB2625383958938 | F21: 8.57AM | G21: YES | H21: LAWRENCE
A22: Iwo 2 Monatan OBX | B22: FCMB | C22: 1609600 | D22: SAHEED ADEBOWALE | G22: YES | H22: ABIMBOLA
A23: Jah Michael TA | B23: FCMB | C23: 2707050 | D23: FADENI & SONS | E23: 120753 | F23: 10.36AM | G23: YES | H23: ABIMBOLA
A24: Moniya OBX
A25: Mowe SGR
A26: Ogbomoso 1 | B26: FCMB | C26: 919200 | D26: JIDE OYEWOLE | E26: 118849 | F26: 10.17AM | G26: YES | H26: ABIMBOLA
A27: Ogbomoso 2 | B27: FCMB | C27: 529315 | D27: OGUNSOLA ADEMOLA | G27: YES | H27: ABIMBOLA
A28: Ogere 1
A29: Ogere 2
A30: Ogijo | B30: FCMB | C30: 1495550 | D30: MUBARAK AFOLABI | E30: 22769184 | G30: YES | H30: ABIMBOLA
A31: Ojoo
A32: Olomi 1 | B32: FCMB | C32: 828600 | D32: DONALD NWAKWO | E32: 23480835 | G32: YES | H32: ABIMBOLA
A33: Olomi 2
A34: Olorunsogo | B34: FCMB | C34: 842000 | D34: ADEPEJU TITILAYO | E34: 23480834 | G34: YES | H34: ABIMBOLA
A35: Oyo Ilora
A36: Sagam 1 | B36: UNION | C36: 3940950 | D36: GBADEBO TEMITOPE | G36: YES | H36: LAWRENCE
A37: Sagam 2 | B37: FCMB | C37: 1640600 | D37: AJAYI ENIOLA | E37: 139322 | F37: 1.12PM | G37: YES | H37: ABIMBOLA
A38: Sagam 3
A39: Sagam 4 | B39: UNION | C39: 1361350 | D39: OLUWABUSOLAMI | E39: FJB26253839782425 | F39: 12.34PM | G39: YES | H39: LAWRENCE
A40: Shapade
...

Sheet 11-09-2026
A1: Stations | B1: Bank Account | C1: Amount | D1: Depositor's Name | E1: Trans. Ref | F1: Lodgement Time | G1: Confirmed Y/N | H1: Confirmed By
A2: Agbara 1 | B2: ZENITH | C2: 2293800 | D2: ADEKUNLE IBIKUNLE | E2: 21286301 | G2: NO
A3: Agodi OBX | B3: FCMB | C3: 404850 | D3: ALABI OMOWUNMI | E3: 149236 | F3: 1.43PM | G3: YES | H3: ABIMBOLA
A4: Alegi SGX
A5: Apata SGR | B5: FCMB | C5: 974550 | D5: BABATUNDE EBENEZER | E5: 23480363 | G5: YES | H5: ABIMBOLA
A6: Bodija OBX | B6: FCMB | C6: 491000 | D6: IYIOLA QUADRI | E6: 25461716 | G6: YES | H6: ABIMBOLA
A7: Cargo 1 OBX | B7: FCMB | C7: 880500 | D7: KOLAWOLE EDUN | E7: 14081655 | G7: YES | H7: ABIMBOLA
A8: Cargo 2 OBX | B8: UNION | C8: 1298800 | D8: JINAUD IBRAHIM | E8: 10.54AM | G8: YES | H8: LAWRENCE
A9: Challenge OBX
A10: Guru OBX | B10: UNION | C10: 4091600 | D10: OJUMOOLA | E10: 4.23PM | G10: YES | H10: LAWRENCE
A11: Iba 1 | B11: FCMB | C11: 4427520 | D11: GBOLAGADE AYOMIKUN | G11: YES | H11: ABIMBOLA
A12: IBA 2 | B12: ZENITH | C12: 3164300 | D12: TAIWO BUKOLA | E12: 42632 | G12: NO
A13: Ife 1 OBX | B13: FCMB | C13: 1467450 | D13: ADEDIRAN MEMUNAT | G13: YES | H13: ABIMBOLA
A14: Ife 2 OBX | B14: FCMB | C14: 202600 | D14: AKORIN OLAITAN | E14: 139566 | F14: 12.16PM | G14: YES | H14: ABIMBOLA
A15: Ife 3 OBX | B15: FCMB | C15: 914260 | D15: TEMIDAYO DAVID | G15: YES | H15: ABIMBOLA
A16: Igbesa AGS
A17: Ijebu 1 SGR | B17: FCMB | C17: 1329100 | D17: BABATUNDE AJAWESORO | E17: 24596129 | G17: YES | H17: ABIMBOLA
A18: Ijebu 2 SGR | B18: FCMB | C18: 1120200 | D18: ADENIJI ADUNOLA | G18: YES | H18: ABIMBOLA
A19: Interchange SGR
A20: Itamaga SGR | B20: UNION | C20: 2563000 | D20: BARAKAT | E20: FJB2625484009318 | G20: YES | H20: LAWRENCE
A21: Iwo 1 OBX | B21: UNION | C21: 1010850 | D21: FUNMILAYO TALABI | E21: FJB2625483998788 | F21: 8.40AM | G21: YES | H21: LAWRENCE
A22: Iwo 2 Monatan OBX | B22: FCMB | C22: 1678720 | D22: SAHEED ADEBOWALE | G22: YES | H22: ABIMBOLA
A23: Jah Michael TA | B23: FCMB | C23: 2000000 | D23: FADENI & SONS | F23: 7.30AM | G23: YES | H23: ABIMBOLA
A24: Jah Michael TA | B24: FCMB | C24: 450000 | D24: FADENI & SONS | F24: 9.32AM | G24: YES | H24: ABIMBOLA
A25: Moniya OBX | B25: FCMB | C25: 965450 | D25: OLUNIYI OLANIRAN | F25: 9.10AM | G25: YES | H25: ABIMBOLA
A26: Mowe SGR | B26: ZENITH | C26: 9342000 | D26: OWOYELE BUKOLA | E26: 728299 | G26: NO
A27: Ogbomoso 1 | B27: FCMB | C27: 908050 | D27: JIDE OYEWOLE | E27: 129557 | F27: 10.26AM | G27: YES | H27: ABIMBOLA
A28: Ogbomoso 2 | B28: FCMB | C28: 372805 | D28: OGUNSOLA ADEMOLA | G28: YES | H28: ABIMBOLA
A29: Ogere 1 | B29: UNION | C29: 1500000 | D29: FJB2625483998766 | E29: FJB2625483998766 | F29: 9.30AM | G29: YES | H29: LAWRENCE
A30: Ogere 2
A31: Ogijo | B31: FCMB | C31: 1345850 | D31: MUBARAK AFOLABI | E31: 23131334 | G31: YES | H31: ABIMBOLA
A32: Ojoo
A33: Olomi 1
A34: Olomi 2 | B34: FCMB | C34: 1789770 | D34: ASAKULA TAIWO | E34: 23480360 | G34: YES | H34: ABIMBOLA
A35: Olorunsogo | B35: FCMB | C35: 1027200 | D35: ADEPEJU TITILAYO | E35: 23480353 | G35: YES | H35: ABIMBOLA
A36: Oyo Ilora | B36: UNION | C36: 1256320 | D36: ABIOLA | F36: 11.30AM | G36: YES | H36: LAWRENCE
A37: Sagam 1 | B37: UNION | C37: 4451300 | D37: GBADEBO TEMITOPE | E37: 962032 | G37: YES | H37: LAWRENCE
A38: Sagam 2 | B38: FCMB | C38: 1817400 | D38: AJAYI ENIOLA | E38: 154664 | F38: 2.32PM | G38: YES | H38: ABIMBOLA
A39: Sagam 3
A40: Sagam 4 | B40: UNION | C40: 1172500 | D40: OLUWABUSOLAMI | E40: 9417 | G40: YES | H40: LAWRNCE
...

Sheet 12-09-2026
A1: Stations | B1: Bank Account | C1: Amount | D1: Depositor's Name | E1: Trans. Ref | F1: Lodgement Time | G1: Confirmed Y/N | H1: Confirmed By
A2: Agbara 1 | B2: ZENITH | D2: ADEKUNLE IBIKUNLE
A3: Agodi OBX | B3: FCMB | D3: ALABI OMOWUNMI
A4: Alegi SGX
A5: Apata SGR | B5: FCMB | D5: BABATUNDE EBENEZER
A6: Bodija OBX | B6: FCMB | D6: IYIOLA QUADRI
A7: Cargo 1 OBX | B7: FCMB | D7: KOLAWOLE EDUN
A8: Cargo 2 OBX | B8: UNION | D8: JINAUD IBRAHIM
A9: Challenge OBX
A10: Guru OBX | B10: UNION | D10: OJUMOOLA
A11: Iba 1 | B11: FCMB | D11: GBOLAGADE AYOMIKUN
A12: IBA 2 | B12: ZENITH | D12: TAIWO BUKOLA
A13: Ife 1 OBX | B13: FCMB | D13: ADEDIRAN MEMUNAT
A14: Ife 2 OBX | B14: FCMB | D14: AKORIN OLAITAN
A15: Ife 3 OBX | B15: FCMB | D15: TEMIDAYO DAVID
A16: Igbesa AGS
A17: Ijebu 1 SGR | B17: FCMB | D17: BABATUNDE AJAWESORO
A18: Ijebu 2 SGR | B18: FCMB | D18: ADENIJI ADUNOLA
A19: Interchange SGR
A20: Itamaga SGR | B20: UNION | D20: BARAKAT
A21: Iwo 1 OBX | B21: UNION | D21: FUNMILAYO TALABI
A22: Iwo 2 Monatan OBX | B22: FCMB | D22: SAHEED ADEBOWALE
A23: Jah Michael TA | B23: FCMB | C23: 1000000 | D23: FADENI & SONS | F23: 6.49AM | G23: YES | H23: ABIMBOLA
A24: Moniya OBX | B24: FCMB | D24: OLUNIYI OLANIRAN
A25: Mowe SGR | B25: ZENITH | D25: OWOYELE BUKOLA
A26: Ogbomoso 1 | B26: FCMB | D26: JIDE OYEWOLE
A27: Ogbomoso 2 | B27: FCMB | D27: OGUNSOLA ADEMOLA
A28: Ogere 1 | B28: UNION | D28: FJB2625483998766
A29: Ogere 2
A30: Ogijo | B30: FCMB | D30: MUBARAK AFOLABI
A31: Ojoo
A32: Olomi 1
A33: Olomi 2 | B33: FCMB | D33: ASAKULA TAIWO
A34: Olorunsogo | B34: FCMB | D34: ADEPEJU TITILAYO
A35: Oyo Ilora | B35: UNION | D35: ABIOLA
A36: Sagam 1 | B36: UNION | D36: GBADEBO TEMITOPE
A37: Sagam 2 | B37: FCMB | D37: AJAYI ENIOLA
A38: Sagam 3
A39: Sagam 4 | B39: UNION | D39: OLUWABUSOLAMI
A40: Shapade
...

Sheet 13-09-2026
A1: Stations | B1: Bank Account | C1: Amount | D1: Depositor's Name | E1: Trans. Ref | F1: Lodgement Time | G1: Confirmed Y/N | H1: Confirmed By
A2: Agbara 1 | B2: ZENITH | D2: ADEKUNLE IBIKUNLE
A3: Agodi OBX | B3: FCMB | D3: ALABI OMOWUNMI
A4: Alegi SGX
A5: Apata SGR | B5: FCMB | D5: BABATUNDE EBENEZER
A6: Bodija OBX | B6: FCMB | D6: IYIOLA QUADRI
A7: Cargo 1 OBX | B7: FCMB | D7: KOLAWOLE EDUN
A8: Cargo 2 OBX | B8: UNION | D8: JINAUD IBRAHIM
A9: Challenge OBX
A10: Guru OBX | B10: UNION | D10: OJUMOOLA
A11: Iba 1 | B11: FCMB | D11: GBOLAGADE AYOMIKUN
A12: IBA 2 | B12: ZENITH | D12: TAIWO BUKOLA
A13: Ife 1 OBX | B13: FCMB | D13: ADEDIRAN MEMUNAT
A14: Ife 2 OBX | B14: FCMB | D14: AKORIN OLAITAN
A15: Ife 3 OBX | B15: FCMB | D15: TEMIDAYO DAVID
A16: Igbesa AGS
A17: Ijebu 1 SGR | B17: FCMB | D17: BABATUNDE AJAWESORO
A18: Ijebu 2 SGR | B18: FCMB | D18: ADENIJI ADUNOLA
A19: Interchange SGR
A20: Itamaga SGR | B20: UNION | D20: BARAKAT
A21: Iwo 1 OBX | B21: UNION | D21: FUNMILAYO TALABI
A22: Iwo 2 Monatan OBX | B22: FCMB | D22: SAHEED ADEBOWALE
A23: Jah Michael TA | B23: FCMB | D23: FADENI & SONS
A24: Moniya OBX | B24: FCMB | D24: OLUNIYI OLANIRAN
A25: Mowe SGR | B25: ZENITH | D25: OWOYELE BUKOLA
A26: Ogbomoso 1 | B26: FCMB | D26: JIDE OYEWOLE
A27: Ogbomoso 2 | B27: FCMB | D27: OGUNSOLA ADEMOLA
A28: Ogere 1 | B28: UNION | D28: FJB2625483998766
A29: Ogere 2
A30: Ogijo | B30: FCMB | D30: MUBARAK AFOLABI
A31: Ojoo
A32: Olomi 1
A33: Olomi 2 | B33: FCMB | D33: ASAKULA TAIWO
A34: Olorunsogo | B34: FCMB | D34: ADEPEJU TITILAYO
A35: Oyo Ilora | B35: UNION | D35: ABIOLA
A36: Sagam 1 | B36: UNION | D36: GBADEBO TEMITOPE
A37: Sagam 2 | B37: FCMB | D37: AJAYI ENIOLA
A38: Sagam 3
A39: Sagam 4 | B39: UNION | D39: OLUWABUSOLAMI
A40: Shapade
...

Sheet 14-09-2026
A1: Stations | B1: Bank Account | C1: Amount | D1: Depositor's Name | E1: Trans. Ref | F1: Lodgement Time | G1: Confirmed Y/N | H1: Confirmed By
A2: Agbara 1 | B2: ZENITH | C2: 6781400 | D2: ADEKUNLE IBIKUNLE | E2: 21206346 | G2: NO
A3: Agodi OBX | B3: FCMB | C3: 2336450 | D3: ALABI OMOWUNMI | G3: YES | H3: ABIMBOLA
A4: Alegi SGX
A5: Apata SGR | B5: FCMB | C5: 3594200 | D5: BABATUNDE EBENEZER | E5: 23480376 | G5: YES | H5: ABIMBOLA
A6: Bodija OBX | B6: FCMB | C6: 1402100 | D6: IYIOLA QUADRI | E6: 25461749 | G6: YES | H6: ABIMBOLA
A7: Cargo 1 OBX | B7: FCMB | C7: 2366900 | D7: KOLAWOLE EDUN | E7: 23480721 | G7: YES | H7: ABIMBOLA
A8: Cargo 2 OBX | B8: UNION | C8: 1956550 | D8: JINAUD IBRAHIM | E8: FJB262578405 | F8: 01:17PM | G8: YES | H8: LAWRENCE
A9: Challenge OBX | B9: FCMB | C9: 3397870 | D9: ASISAT | E9: 23480365 | G9: YES | H9: ABIMBOLA
A10: Guru OBX | B10: UNION | C10: 14401100 | D10: OJUMOOLA | E10: FJB262578840 | F10: 03:48PM | G10: YES | H10: LAWRENCE
A11: Iba 1 | B11: FCMB | C11: 4054200 | D11: GBOLAGADE AYOMIKUN | G11: YES | H11: ABIMBOLA
A12: IBA 2 | B12: ZENITH | C12: 9469300 | D12: TAIWO BUKOLA | G12: NO
A13: Ife 1 OBX | B13: FCMB | C13: 2557410 | D13: ABDULSALAM OPEYEMI | G13: YES | H13: ABIMBOLA
A14: Ife 2 OBX | B14: FCMB | C14: 726100 | D14: AKORIN OLAITAN | E14: 1234165 | G14: YES | H14: ABIMBOLA
A15: Ife 3 OBX | B15: FCMB | C15: 3305440 | D15: TEMIDAYO DAVID | E15: 1230943 | G15: YES | H15: ABIMBOLA
A16: Igbesa AGS
A17: Ijebu 1 SGR | B17: FCMB | C17: 4848400 | D17: BABATUNDE AJAWESORO | E17: 24596038 | G17: YES | H17: ABIMBOLA
A18: Ijebu 2 SGR | B18: FCMB | C18: 2100000 | D18: ADENIJI ADUNOLA | G18: YES | H18: ABIMBOLA
A19: Interchange SGR
A20: Itamaga SGR | B20: UNION | C20: 8531050 | D20: BARAKAT | E20: FJB2625784035022 | F20: 9:35AM | G20: YES | H20: LAWRENCE
A21: Iwo 1 OBX | B21: UNION | C21: 2735800 | D21: MARY | E21: FJB2625784036305 | F21: 9:11AM | G21: YES | H21: LAWRENCE
A22: Iwo 2 Monatan OBX | B22: FCMB | C22: 5091420 | D22: SAHEED ADEBOWALE | G22: YES | H22: ABIMBOLA
A23: Jah Michael TA | B23: FCMB | C23: 2342050 | D23: POPOOLA ADISA | E23: 1230564 | G23: YES | H23: ABIMBOLA
A24: Moniya OBX | B24: FCMB | D24: OLUNIYI OLANIRAN
A25: Mowe SGR | B25: ZENITH | D25: OWOYELE BUKOLA
A26: Ogbomoso 1 | B26: FCMB | C26: 2544490 | D26: JIDE OYEWOLE | E26: 1226929 | F26: 9:52AM | G26: YES | H26: ABIMBOLA
A27: Ogbomoso 2 | B27: FCMB | C27: 1858165 | D27: OGUNSOLA ADEMOLA | E27: 1232712 | F27: 11:09AM | G27: YES | H27: ABIMBOLA
A28: Ogere 1 | B28: UNION | D28: FJB2625483998766
A29: Ogere 2
A30: Ogijo | B30: FCMB | C30: 4854200 | D30: MUBARAK AFOLABI | G30: YES | H30: ABIMBOLA
A31: Ojoo
A32: Olomi 1 | B32: FCMB | C32: 2069600 | D32: DONALD NWANKWO | G32: YES | H32: ABIMBOLA
A33: Olomi 2 | B33: FCMB | C33: 1789770 | D33: ASAKULA TAIWO | E33: 23480360 | G33: NO
A34: Olorunsogo | B34: FCMB | C34: 4356900 | D34: ADEPEJU TITILAYO | E34: 23480372 | G34: YES | H34: ABIMBOLA
A35: Oyo Ilora | B35: UNION | C35: 2198000 | D35: ABIOLA | E35: FJB2625784 | F35: 11:35AM | G35: YES | H35: LAWRENCE
A36: Sagam 1 | B36: UNION | C36: 7561200 | D36: GBADEBO TEMITOPE | E36: 50096451 | G36: YES | H36: LAWRENCE
A37: Sagam 2 | B37: FCMB | C37: 1540900 | D37: AJAYI ENIOLA | E37: 1239767 | F37: 12:24PM | G37: YES | H37: ABIMBOLA
A38: Sagam 3
A39: Sagam 4 | B39: UNION | C39: 1309350 | D39: OLUWABUSOLAMI | G39: YES | H39: LAWRENCE
A40: Shapade | B40: FCMB | C40: 7000000 | D40: OLAWUNMI | E40: 1246500 | F40: 1:17PM | G40: YES | H40: ABIMBOLA
...

Sheet 15-09-2026
A1: Stations | B1: Bank Account | C1: Amount | D1: Depositor's Name | E1: Trans. Ref | F1: Lodgement Time | G1: Confirmed Y/N | H1: Confirmed By
A2: Agbara 1 | B2: ZENITH | C2: 3143100 | D2: ADEKUNLE IBIKUNLE | E2: 134728 | F2: 12:37PM | G2: YES | H2: ABIMBOLA
A3: Agodi OBX | B3: FCMB | C3: 963300 | D3: ALABI OMOWUNMI | G3: YES | H3: ABIMBOLA
A4: Alegi SGX
A5: Apata SGR | B5: FCMB | C5: 882120 | D5: BABATUNDE EBENEZER | E5: 23480217 | G5: YES | H5: ABIMBOLA
A6: Bodija OBX | B6: FCMB | C6: 393500 | D6: IYIOLA QUADRI | E6: 25461307 | G6: YES | H6: ABIMBOLA
A7: Cargo 1 OBX | B7: FCMB | C7: 1414050 | D7: KOLAWOLE EDUN | E7: 14081665 | G7: YES | H7: ABIMBOLA
A8: Cargo 2 OBX | B8: UNION | C8: 1158050 | D8: JINAUD IBRAHIM | E8: FJB2625884078 | F8: 10:46AM | G8: YES | H8: LAWRENCE
A9: Challenge OBX | B9: FCMB | D9: ASISAT
A10: Guru OBX | B10: UNION | C10: 4859800 | D10: OJUMOOLA | E10: FJB282588 | G10: YES | H10: LAWRENCE
A11: Iba 1 | B11: FCMB | D11: GBOLAGADE AYOMIKUN
A12: IBA 2 | B12: ZENITH | C12: 3113000 | D12: TAIWO BUKOLA | E12: 42627 | G12: NO
A13: Ife 1 OBX | B13: FCMB | C13: 945150 | D13: ABDULSALAM OPEYEMI | G13: YES | H13: ABIMBOLA
A14: Ife 2 OBX | B14: FCMB | C14: 298700 | D14: AKORIN OLAITAN | E14: 130715 | F14: 12:09PM | G14: YES | H14: ABIMBOLA
A15: Ife 3 OBX | B15: FCMB | C15: 1477070 | D15: TEMIDAYO DAVID | G15: YES | H15: ABIMBOLA
A16: Igbesa AGS
A17: Ijebu 1 SGR | B17: FCMB | C17: 2319400 | D17: BABATUNDE AJAWESORO | E17: 24596034 | G17: YES | H17: ABIMBOLA
A18: Ijebu 2 SGR | B18: FCMB | C18: 802500 | D18: ADENIJI ADUNOLA | G18: YES | H18: ABIMBOLA
A19: Interchange SGR
A20: Itamaga SGR | B20: UNION | C20: 4061100 | D20: BARAKAT | E20: FJB2025884083210 | F20: 9:34AM | G20: YES | H20: LAWRENCE
A21: Iwo 1 OBX | B21: UNION | C21: 700120 | D21: MARY | E21: FJB2625884074107 | F21: 8:41AM | G21: NO
A22: Iwo 2 Monatan OBX | B22: FCMB | C22: 1645960 | D22: SAHEED ADEBOWALE | G22: YES | H22: ABIMBOLA
A23: Jah Michael TA | B23: FCMB | C23: 684970 | D23: POPOOLA ADISA | G23: YES
A24: Moniya OBX | B24: FCMB | C24: 1207700 | D24: OLUNIYI OLANIRAN | E24: 25461334 | G24: YES | H24: ABIMBOLA
A25: Mowe SGR | B25: ZENITH | C25: 4856400 | D25: OWOYELE BUKOLA | E25: 718295 | G25: NO
A26: Ogbomoso 1 | B26: FCMB | C26: 1082800 | D26: JIDE OYEWOLE | E26: 119092 | F26: 9:32AM | G26: YES | H26: ABIMBOLA
A27: Ogbomoso 2 | B27: FCMB | C27: 502035 | D27: OGUNSOLA ADEMOLA | E27: 124491 | F27: 11:00AM | G27: YES | H27: ABIMBOLA
A28: Ogere 1 | B28: UNION | D28: FJB2625483998766
A29: Ogere 2
A30: Ogijo | B30: FCMB | C30: 1039050 | D30: MUBARAK AFOLABI | G30: YES | H30: ABIMBOLA
A31: Ojoo
A32: Olomi 1 | B32: FCMB | C32: 617350 | D32: DONALD NWANKWO | E32: 23480218 | G32: YES | H32: ABIMBOLA
A33: Olomi 2 | B33: FCMB | D33: ASAKULA TAIWO
A34: Olorunsogo | B34: FCMB | C34: 825000 | D34: ADEPEJU TITILAYO | E34: 23480213 | G34: YES | H34: ABIMBOLA
A35: Oyo Ilora | B35: UNION | C35: 1364200 | D35: ABIOLA | E35: FJB2625884 | G35: YES | H35: LAWRENCE
A36: Sagam 1 | B36: UNION | C36: 1915500 | D36: GBADEBO TEMITOPE | G36: YES | H36: LAWRENCE
A37: Sagam 2 | B37: FCMB | C37: 3597200 | D37: AJAYI ENIOLA | E37: 139121 | F37: 1:38PM | G37: YES | H37: ABIMBOLA
A38: Sagam 3
A39: Sagam 4 | B39: UNION | C39: 925150 | D39: OLUWABUSOLAMI | E39: 5966 | G39: YES | H39: LAWRENCE
A40: Shapade
...

Sheet 16-09-2026
A1: Stations | B1: Bank Account | C1: Amount | D1: Depositor's Name | E1: Trans. Ref | F1: Lodgement Time | G1: Confirmed Y/N | H1: Confirmed By
A2: Agbara 1 | B2: ZENITH | C2: 2473800 | D2: ADEKUNLE IBIKUNLE | G2: NO
A3: Agodi OBX | B3: FCMB | C3: 741550 | D3: ALABI OMOWUNMI | G3: YES | H3: ABIMBOLA
A4: Alegi SGX
A5: Apata SGR | B5: FCMB | C5: 1241650 | D5: BABATUNDE EBENEZER | E5: 23480238 | G5: YES | H5: ABIMBOLA
A6: Bodija OBX | B6: FCMB | C6: 874100 | D6: IYIOLA QUADRI | E6: 25461321 | G6: YES | H6: ABIMBOLA
A7: Cargo 1 OBX | B7: FCMB | C7: 1171700 | D7: KOLAWOLE EDUN | E7: 22698928 | G7: YES | H7: ABIMBOLA
A8: Cargo 2 OBX | B8: UNION | C8: 1471800 | D8: JINAUD IBRAHIM | E8: FJB2625984119 | F8: 10:47AM | G8: YES | H8: LAWRENCE
A9: Challenge OBX | B9: FCMB | C9: 1201300 | D9: ASISAT | E9: 23480229 | G9: YES | H9: ABIMBOLA
A10: Guru OBX | B10: UNION | C10: 3464700 | D10: OJUMOOLA | E10: FJB2625984 | F10: 12:48PM | G10: NO
A11: Iba 1 | B11: FCMB | C11: 4871750 | D11: GBOLAGADE AYOMIKUN | E11: 42325 | G11: NO
A12: IBA 2 | B12: ZENITH | C12: 3400700 | D12: TAIWO BUKOLA | G12: NO
A13: Ife 1 OBX | B13: FCMB | C13: 678540 | D13: ABDULSALAM OPEYEMI | G13: YES | H13: ABIMBOLA
A14: Ife 2 OBX | B14: FCMB | C14: 200600 | D14: AKORIN OLAITAN | E14: 118912 | F14: 8:41AM | G14: YES | H14: ABIMBOLA
A15: Ife 3 OBX | B15: FCMB | C15: 903700 | D15: TEMIDAYO DAVID | G15: YES | H15: ABIMBOLA
A16: Igbesa AGS
A17: Ijebu 1 SGR | B17: FCMB | C17: 1965700 | D17: BABATUNDE AJAWESORO | E17: 24596163 | G17: YES | H17: ABIMBOLA
A18: Ijebu 2 SGR | B18: FCMB | C18: 871500 | D18: ADENIJI ADUNOLA | G18: YES | H18: ABIMBOLA
A19: Interchange SGR
A20: Itamaga SGR | B20: ZENITH | C20: 3246450 | D20: BARAKAT | E20: 769390 | G20: NO
A21: Iwo 1 OBX | B21: UNION | C21: 806900 | D21: MARY | E21: FJB2625984107 | F21: 08:38AM | G21: YES | H21: LAWRENCE
A22: Iwo 2 Monatan OBX | B22: FCMB | C22: 1384700 | D22: SAHEED ADEBOWALE | G22: YES | H22: ABIMBOLA
A23: Jah Michael TA | B23: FCMB | C23: 1468500 | D23: POPOOLA ADISA | E23: 125395 | F23: 9:56AM | G23: YES | H23: ABIMBOLA
A24: Moniya OBX | B24: FCMB | D24: OLUNIYI OLANIRAN
A25: Mowe SGR | B25: ZENITH | D25: OWOYELE BUKOLA
A26: Ogbomoso 1 | B26: FCMB | C26: 884950 | D26: JIDE OYEWOLE | E26: 122308 | F26: 9:17AM | G26: YES | H26: ABIMBOLA
A27: Ogbomoso 2 | B27: FCMB | C27: 255635 | D27: OGUNSOLA ADEMOLA | E27: 128351 | F27: 10:33AM | G27: YES | H27: ABIMBOLA
A28: Ogere 1 | B28: UNION | D28: FJB2625483998766
A29: Ogere 2
A30: Ogijo | B30: FCMB | C30: 1840200 | D30: MUBARAK AFOLABI | E30: 124332 | F30: 09:53AM | G30: YES | H30: ABIMBOLA
A31: Ojoo
A32: Olomi 1 | B32: FCMB | D32: DONALD NWANKWO
A33: Olomi 2 | B33: FCMB | C33: 2099650 | D33: ASAKULA TAIWO | E33: 23480235 | G33: YES | H33: ABIMBOLA
A34: Olorunsogo | B34: FCMB | C34: 1826000 | D34: ADEPEJU TITILAYO | E34: 23480239 | G34: YES | H34: ABIMBOLA
A35: Oyo Ilora | B35: UNION | D35: ABIOLA
A36: Sagam 1 | B36: UNION | C36: 2651800 | D36: GBADEBO TEMITOPE | E36: 4999648 | G36: YES | H36: LAWRENCE
A37: Sagam 2 | B37: FCMB | C37: 2664900 | D37: AJAYI ENIOLA | E37: 137688 | F37: 12:29PM | G37: YES | H37: ABIMBOLA
A38: Sagam 3
A39: Sagam 4 | B39: UNION | C39: 1224200 | D39: OLUWABUSOLAMI | E39: 4975974 | G39: YES | H39: LAWRENCE
A40: Shapade
...

Sheet 17-09-2026
A1: Stations | B1: Bank Account | C1: Amount | D1: Depositor's Name | E1: Trans. Ref | F1: Lodgement Time | G1: Confirmed Y/N | H1: Confirmed By
A2: Agbara 1 | B2: ZENITH | C2: 3037800 | D2: ADEKUNLE IBIKUNLE | E2: 21286343 | G2: NO
A3: Agodi OBX | B3: FCMB | C3: 710350 | D3: ALABI OMOWUNMI | E3: 171002550 | F3: 10:02AM | G3: YES | H3: ABIMBOLA
A4: Alegi SGX | B4: UNION | C4: 498800 | D4: ABUBAKAR MUSA | E4: 2100546985 | F4: 12:33PM | G4: YES | H4: LAWRENCE
A5: Apata SGR | B5: FCMB | C5: 1111500 | D5: BABATUNDE EBENEZER | E5: 23480902 | G5: YES | H5: ABIMBOLA
A6: Bodija OBX | B6: FCMB | C6: 770900 | D6: IYIOLA QUADRI | E6: 25461294 | G6: YES | H6: ABIMBOLA
A7: Cargo 1 OBX | B7: FCMB | C7: 1215200 | D7: KOLAWOLE EDUN | E7: 23480741 | G7: YES | H7: ABIMBOLA
A8: Cargo 2 OBX | B8: UNION | C8: 1240130 | D8: JINAUD IBRAHIM | E8: FJB2626084150 | F8: 11:09AM | G8: YES | H8: LAWRENCE
A9: Challenge OBX | B9: FCMB | C9: 907800 | D9: ASISAT | E9: 23480245 | G9: YES | H9: ABIMBOLA
A10: Guru OBX | B10: UNION | C10: 3566200 | D10: OJUMOOLA | E10: FJB26260841 | G10: YES | H10: LAWRENCE
A11: Iba 1
A12: IBA 2 | B12: ZENITH | C12: 3382800 | D12: TAIWO BUKOLA | E12: 19859966 | G12: NO
A13: Ife 1 OBX | B13: FCMB | C13: 829300 | D13: ABDULSALAM OPEYEMI | G13: YES | H13: ABIMBOLA
A14: Ife 2 OBX | B14: FCMB | C14: 277350 | D14: AKORIN OLAITAN | G14: YES | H14: ABIMBOLA
A15: Ife 3 OBX | B15: FCMB | C15: 980330 | D15: TEMIDAYO DAVID | G15: YES | H15: ABIMBOLA
A16: Igbesa AGS
A17: Ijebu 1 SGR | B17: FCMB | C17: 1778650 | D17: BABATUNDE AJAWESORO | G17: YES | H17: ABIMBOLA
A18: Ijebu 2 SGR | B18: FCMB | D18: ADENIJI ADUNOLA
A19: Interchange SGR
A20: Itamaga SGR | B20: UNION | C20: 3127400 | D20: BARAKAT | E20: FJB262608415 | F20: 11:06AM | G20: YES | H20: LAWRENCE
A21: Iwo 1 OBX | B21: UNION | C21: 821900 | D21: MARY | E21: fjb26260841 | F21: 08:49AM | G21: YES | H21: LAWRENCE
A22: Iwo 2 Monatan OBX | B22: FCMB | C22: 839400 | D22: SAHEED ADEBOWALE | G22: YES | H22: ABIMBOLA
A23: Jah Michael TA | B23: FCMB | C23: 1500000 | D23: FADENI & SON | E23: 2100460724 | F23: 6:43AM | G23: YES | H23: ABIMBOLA
A24: Moniya OBX | B24: FCMB | D24: OLUNIYI OLANIRAN
A25: Mowe SGR | B25: ZENITH | D25: OWOYELE BUKOLA
A26: Ogbomoso 1 | B26: FCMB | C26: 754800 | D26: JIDE OYEWOLE | E26: 137911 | F26: 9:22AM | G26: YES | H26: ABIMBOLA
A27: Ogbomoso 2 | B27: FCMB | C27: 766850 | D27: OGUNSOLA ADEMOLA | G27: YES | H27: ABIMBOLA
A28: Ogere 1 | B28: UNION | D28: FJB2625483998766
A29: Ogere 2
A30: Ogijo | B30: FCMB | C30: 2754000 | D30: MUBARAK AFOLABI | G30: YES
A31: Ojoo
A32: Olomi 1 | B32: FCMB | C32: 826650 | D32: DONALD NWANKWO | E32: 23480901 | G32: YES
A33: Olomi 2 | B33: FCMB | D33: ASAKULA TAIWO
A34: Olorunsogo | B34: FCMB | C34: 1107000 | D34: ADEPEJU TITILAYO | E34: 23480248 | G34: YES | H34: ABIMBOLA
A35: Oyo Ilora | B35: UNION | D35: ABIOLA
A36: Sagam 1 | B36: UNION | C36: 2834900 | D36: GBADEBO TEMITOPE | E36: FJB262608416 | F36: 03:42PM | G36: YES | H36: LAWRENCE
A37: Sagam 2 | B37: FCMB | C37: 1047100 | D37: AJAYI ENIOLA | E37: 1233033 | F37: 11:46AM | G37: YES | H37: ABIMBOLA
A38: Sagam 3
A39: Sagam 4 | B39: UNION | C39: 1127620 | D39: OLUWABUSOLAMI | E39: 8825988 | G39: YES | H39: LAWRENCE
A40: Shapade
...

Sheet 18-09-2026
A1: Stations | B1: Bank Account | C1: Amount | D1: Depositor's Name | E1: Trans. Ref | F1: Lodgement Time | G1: Confirmed Y/N | H1: Confirmed By
A2: Agbara 1 | B2: ZENITH | C2: 1845400 | D2: ADEKUNLE IBIKUNLE | E2: 21286300 | G2: NO | I2: C
A3: Agodi OBX
A4: Alegi SGX | I4: C
A5: Apata SGR | B5: FCMB | C5: 1128700 | D5: BABATUNDE EBENEZER | E5: 23480928 | G5: YES | H5: ABIMBOLA | I5: C
A6: Bodija OBX | B6: FCMB | C6: 544400 | D6: IYIOLA QUADRI | E6: 25461162 | G6: YES | H6: ABIMBOLA | I6: C
A7: Cargo 1 OBX | B7: FCMB | C7: 1034200 | D7: KOLAWOLE EDUN | E7: 23480746 | G7: YES | H7: ABIMBOLA | I7: C
A8: Cargo 2 OBX | B8: UNION | C8: 1160150 | D8: JINAUD IBRAHIM | E8: FJB26262518418 | G8: YES | H8: LAWRENCE | I8: C
A9: Challenge OBX | B9: FCMB | C9: 575270 | D9: ASISAT | E9: 23480912 | G9: YES | H9: ABIMBOLA | I9: C
A10: Guru OBX | B10: UNION | C10: 3659100 | D10: OJUMOOLA | E10: 844496 | G10: YES | H10: LAWRENCE | I10: C
A11: Iba 1 | B11: ZENITH | C11: 4071250 | D11: GBOLAGADE AYOMIKUN | E11: 42328 | G11: NO | I11: C
A12: IBA 2 | B12: ZENITH | C12: 3499000 | D12: TAIWO BUKOLA | E12: 43819 | G12: NO | I12: C
A13: Ife 1 OBX | B13: FCMB | C13: 995450 | D13: ABDULSALAM OPEYEMI | G13: YES | H13: ABIMBOLA | I13: C
A14: Ife 2 OBX | B14: FCMB | C14: 158750 | D14: AKEEM OLAITAN | G14: YES | H14: ABIMBOLA | I14: C
A15: Ife 3 OBX | B15: FCMB | C15: 1217760 | D15: TEMIDAYO DAVID | G15: YES | H15: ABIMBOLA | I15: C
A16: Igbesa AGS
A17: Ijebu 1 SGR | B17: FCMB | C17: 1299700 | D17: BABATUNDE AJAWESORO | E17: 24596257 | G17: YES | H17: ABIMBOLA | I17: C
A18: Ijebu 2 SGR | B18: FCMB | C18: 645700 | D18: ADENIJI ADUNOLA | E18: 121873 | F18: 10.22AM | G18: YES | H18: ABIMBOLA | I18: C
A19: Interchange SGR
A20: Itamaga SGR | B20: UNION | C20: 2790550 | D20: BARAKAT | E20: FJB2626184212858 | F20: 11.23AM | G20: YES | H20: LAWRENCE | I20: C
A21: Iwo 1 OBX | B21: UNION | C21: 729900 | D21: MARY | E21: FJB2626184193512 | F21: 8.48AM | G21: YES | H21: LAWRENCE | I21: C
A22: Iwo 2 Monatan OBX | B22: FCMB | C22: 1163920 | D22: SAHEED ADEBOWALE | G22: YES | H22: ABIMBOLA | I22: C
A23: Jah Michael TA | B23: FCMB | C23: 1872900 | D23: FADENI & SON | E23: 120322 | F23: 10.15AM | G23: YES | H23: ABIMBOLA | I23: C
A24: Moniya OBX | B24: FCMB | C24: 1515250 | D24: OLUNIYI OLANIRAN | E24: 25461155 | G24: YES | H24: ABIMBOLA | I24: C
A25: Mowe SGR | B25: ZENITH | C25: 7191850 | D25: OWOYELE BUKOLA | E25: 6770047 | G25: NO | I25: C
A26: Ogbomoso 1 | B26: FCMB | C26: 1264550 | D26: JIDE OYEWOLE | E26: 20557230 | F26: 9.49AM | G26: YES | H26: ABIMBOLA | I26: C
A27: Ogbomoso 2 | B27: FCMB | C27: 879275 | D27: OGUNSOLA ADEMOLA | E27: 123637 | F27: 10.35AM | G27: YES | H27: ABIMBOLA | I27: C
A28: Ogere 1 | B28: UNION | C28: 3500000 | D28: FOLUWASO | E28: FJB2626184196923 | F28: 10.10AM | G28: YES | H28: LAWRENCE | I28: C
A29: Ogere 2
A30: Ogijo | B30: FCMB | C30: 1709500 | D30: MUBARAK AFOLABI | G30: YES | H30: ABIMBOLA | I30: C
A31: Ojoo
A32: Olomi 1
A33: Olomi 2 | B33: FCMB | C33: 1802800 | D33: ASAKULA TAIWO | E33: 23480920 | G33: YES | H33: ABIMBOLA | I33: C
A34: Olorunsogo | B34: FCMB | C34: 1432000 | D34: ADEPEJU TITILAYO | E34: 23480913 | G34: YES | H34: ABIMBOLA | I34: C
A35: Oyo Ilora | B35: UNION | C35: 2246100 | D35: ABIOLA | F35: 11.12AM | G35: YES | H35: LAWRENCE | I35: C
A36: Sagam 1 | B36: UNION | C36: 3873200 | D36: GBADEBO TEMITOPE | E36: 998862 | G36: YES | H36: LAWRENCE | I36: C
A37: Sagam 2 | B37: FCMB | C37: 2103700 | D37: AJAYI ENIOLA | E37: 130069 | F37: 12.21PM | G37: YES | H37: ABIMBOLA | I37: C
A38: Sagam 3
A39: Sagam 4 | B39: UNION | C39: 1357150 | D39: OLUWABUSOLAMI | E39: 8960 | G39: YES | H39: LAWRENCE | I39: C
A40: Shapade
...

Sheet 19-09-2026
A1: Stations | B1: Bank Account | C1: Amount | D1: Depositor's Name | E1: Trans. Ref | F1: Lodgement Time | G1: Confirmed Y/N | H1: Confirmed By
A2: Agbara 1 | B2: ZENITH | D2: ADEKUNLE IBIKUNLE
A3: Agodi OBX
A4: Alegi SGX
A5: Apata SGR | B5: FCMB | D5: BABATUNDE EBENEZER
A6: Bodija OBX | B6: FCMB | D6: IYIOLA QUADRI
A7: Cargo 1 OBX | B7: FCMB | D7: KOLAWOLE EDUN
A8: Cargo 2 OBX | B8: UNION | D8: JINAUD IBRAHIM
A9: Challenge OBX | B9: FCMB | D9: ASISAT
A10: Guru OBX | B10: UNION | D10: OJUMOOLA
A11: Iba 1 | B11: ZENITH | D11: GBOLAGADE AYOMIKUN
A12: IBA 2 | B12: ZENITH | D12: TAIWO BUKOLA
A13: Ife 1 OBX | B13: FCMB | D13: ABDULSALAM OPEYEMI
A14: Ife 2 OBX | B14: FCMB | D14: AKEEM OLAITAN
A15: Ife 3 OBX | B15: FCMB | D15: TEMIDAYO DAVID
A16: Igbesa AGS
A17: Ijebu 1 SGR | B17: FCMB | D17: BABATUNDE AJAWESORO
A18: Ijebu 2 SGR | B18: FCMB | D18: ADENIJI ADUNOLA
A19: Interchange SGR
A20: Itamaga SGR | B20: UNION | D20: BARAKAT
A21: Iwo 1 OBX | B21: UNION | D21: MARY
A22: Iwo 2 Monatan OBX | B22: FCMB | D22: SAHEED ADEBOWALE
A23: Jah Michael TA | B23: FCMB | D23: FADENI & SON
A24: Moniya OBX | B24: FCMB | D24: OLUNIYI OLANIRAN
A25: Mowe SGR | B25: ZENITH | D25: OWOYELE BUKOLA
A26: Ogbomoso 1 | B26: FCMB | D26: JIDE OYEWOLE
A27: Ogbomoso 2 | B27: FCMB | D27: OGUNSOLA ADEMOLA
A28: Ogere 1 | B28: UNION | D28: FOLUWASO
A29: Ogere 2
A30: Ogijo | B30: FCMB | D30: MUBARAK AFOLABI
A31: Ojoo
A32: Olomi 1
A33: Olomi 2 | B33: FCMB | D33: ASAKULA TAIWO
A34: Olorunsogo | B34: FCMB | D34: ADEPEJU TITILAYO
A35: Oyo Ilora | B35: UNION | D35: ABIOLA
A36: Sagam 1 | B36: UNION | D36: GBADEBO TEMITOPE
A37: Sagam 2 | B37: FCMB | D37: AJAYI ENIOLA
A38: Sagam 3
A39: Sagam 4 | B39: UNION | D39: OLUWABUSOLAMI
A40: Shapade
...

Sheet 20-09-2026
A1: Stations | B1: Bank Account | C1: Amount | D1: Depositor's Name | E1: Trans. Ref | F1: Lodgement Time | G1: Confirmed Y/N | H1: Confirmed By
A2: Agbara 1 | B2: ZENITH | D2: ADEKUNLE IBIKUNLE
A3: Agodi OBX
A4: Alegi SGX
A5: Apata SGR | B5: FCMB | D5: BABATUNDE EBENEZER
A6: Bodija OBX | B6: FCMB | D6: IYIOLA QUADRI
A7: Cargo 1 OBX | B7: FCMB | D7: KOLAWOLE EDUN
